<?xml version="1.0" encoding="utf-8" ?>
<!-- =================================================================================== -->
<!-- |    This document was autogenerated by xacro from /home/acandeias/ROSws/feedbot_ws/src/niryo_one_ros/feedbot_description/urdf/feedbot_v2_wmesh.urdf.xacro | -->
<!-- |    EDITING THIS FILE BY HAND IS NOT RECOMMENDED                                 | -->
<!-- =================================================================================== -->
<!--
    niryo_one.urdf.xacro
    Copyright (C) 2017 Niryo
    All rights reserved.

    This program is free software: you can redistribute it and/or modify
    it under the terms of the GNU General Public License as published by
    the Free Software Foundation, either version 3 of the License, or
    (at your option) any later version.

    This program is distributed in the hope that it will be useful,
    but WITHOUT ANY WARRANTY; without even the implied warranty of
    MERCHANTABILITY or FITNESS FOR A PARTICULAR PURPOSE.  See the
    GNU General Public License for more details.

    You should have received a copy of the GNU General Public License
    along with this program.  If not, see <http://www.gnu.org/licenses/>.
-->
<robot name="niryo_one" xmlns:xacro="http://www.ros.org/wiki/xacro">
    <!-- Properties -->
    <gazebo reference="ground_link">
        <turnGravityOff>true</turnGravityOff>
    </gazebo>
    <gazebo reference="base_link">
        <turnGravityOff>true</turnGravityOff>
    </gazebo>
    <gazebo reference="shoulder_link">
        <turnGravityOff>true</turnGravityOff>
    </gazebo>
    <gazebo reference="arm_link">
        <turnGravityOff>true</turnGravityOff>
    </gazebo>
    <gazebo reference="elbow_link">
        <turnGravityOff>true</turnGravityOff>
    </gazebo>
    <gazebo reference="forearm_link">
        <turnGravityOff>true</turnGravityOff>
    </gazebo>
    <gazebo reference="wrist_link">
        <turnGravityOff>true</turnGravityOff>
    </gazebo>
    <gazebo reference="hand_link">
        <turnGravityOff>true</turnGravityOff>
    </gazebo>
    <gazebo reference="tool_link">
        <turnGravityOff>true</turnGravityOff>
    </gazebo>
    <!--transmission-->
    <transmission name="base_shoulder_transmission">
        <type>transmission_interface/SimpleTransmission</type>
        <joint name="joint_1">
            <hardwareInterface>hardware_interface/PositionJointInterface</hardwareInterface>
        </joint>
        <actuator name="base_shoulder_stepper">
            <mechanicalReduction>6.0625</mechanicalReduction>
            <hardwareInterface>hardware_interface/PositionJointInterface</hardwareInterface>
        </actuator>
    </transmission>
    <transmission name="shoulder_arm_transmission">
        <type>transmission_interface/SimpleTransmission</type>
        <joint name="joint_2">
            <hardwareInterface>hardware_interface/PositionJointInterface</hardwareInterface>
        </joint>
        <actuator name="shoulder_arm_stepper">
            <mechanicalReduction>8.3125</mechanicalReduction>
            <hardwareInterface>hardware_interface/PositionJointInterface</hardwareInterface>
        </actuator>
    </transmission>
    <transmission name="arm_elbow_transmission">
        <type>transmission_interface/SimpleTransmission</type>
        <joint name="joint_3">
            <hardwareInterface>hardware_interface/PositionJointInterface</hardwareInterface>
        </joint>
        <actuator name="arm_elbow_stepper">
            <mechanicalReduction>7.875</mechanicalReduction>
            <hardwareInterface>hardware_interface/PositionJointInterface</hardwareInterface>
        </actuator>
    </transmission>
    <transmission name="elbow_forarm_transmission">
        <type>transmission_interface/SimpleTransmission</type>
        <joint name="joint_4">
            <hardwareInterface>hardware_interface/PositionJointInterface</hardwareInterface>
        </joint>
        <actuator name="elbow_forarm_motor">
            <mechanicalReduction>5.0</mechanicalReduction>
        </actuator>
    </transmission>
    <transmission name="forarm_wirst_transmission">
        <type>transmission_interface/SimpleTransmission</type>
        <joint name="joint_5">
            <hardwareInterface>hardware_interface/PositionJointInterface</hardwareInterface>
        </joint>
        <actuator name="forarm_wirst_motor">
            <mechanicalReduction>1</mechanicalReduction>
        </actuator>
    </transmission>
    <transmission name="wirst_gripper_transmission">
        <type>transmission_interface/SimpleTransmission</type>
        <joint name="joint_6">
            <hardwareInterface>hardware_interface/PositionJointInterface</hardwareInterface>
        </joint>
        <actuator name="wirst_gripper_motor">
            <mechanicalReduction>1</mechanicalReduction>
        </actuator>
    </transmission>
    <!-- Links -->
    <link name="ground_link" />
    <link name="base_link">
        <visual>
            <origin rpy="0 0 0" xyz="0 0 0" />
            <geometry>
                <mesh filename="package://niryo_one_description/meshes/v2/collada/base_link.dae" />
            </geometry>
        </visual>
        <collision>
            <origin rpy="0 0 0" xyz="0 0 0" />
            <geometry>
                <mesh filename="package://niryo_one_description/meshes/v2/stl/base_link.stl" />
            </geometry>
        </collision>
        
        <inertial>
            <origin rpy="0 0 0" xyz="0 0 0" />
            <mass value="2" />
            <!--to change-->
            <inertia ixx="0.0" ixy="0.0" ixz="0.0" iyy="0.0" iyz="0.0" izz="0.0" />
        </inertial>

    </link>
    <link name="shoulder_link">
        <visual>
            <origin rpy="0 0 0" xyz="0 0 0" />
            <geometry>
                <mesh filename="package://niryo_one_description/meshes/v2/collada/shoulder_link.dae" />
            </geometry>
        </visual>
        <collision>
            <origin rpy="0 0 0" xyz="0 0 0" />
            <geometry>
                <mesh filename="package://niryo_one_description/meshes/v2/stl/shoulder_link.stl" />
            </geometry>
        </collision>
        
        <inertial>
            <origin rpy="0 0 0" xyz="0 0 0" />
            <mass value="1" />
            <inertia ixx="1.0" ixy="0.0" ixz="0.0" iyy="1.0" iyz="0.0" izz="1.0" />
        </inertial>

    </link>
    <link name="arm_link">
        <visual>
            <origin rpy="0 0 0" xyz="0 0 0" />
            <geometry>
                <mesh filename="package://niryo_one_description/meshes/v2/collada/arm_link.dae" />
            </geometry>
        </visual>
        <collision>
            <origin rpy="0 0 0" xyz="0 0 0" />
            <geometry>
                <mesh filename="package://niryo_one_description/meshes/v2/stl/arm_link.stl" />
            </geometry>
        </collision>
        
        <inertial>
            <origin rpy="0 0 0" xyz="0 0 0" />
            <mass value="0.5" />
            <inertia ixx="1.0" ixy="0.0" ixz="0.0" iyy="1.0" iyz="0.0" izz="1.0" />
        </inertial>

    </link>
    <link name="elbow_link">
        <visual>
            <origin rpy="0 0 0" xyz="0 0 0" />
            <geometry>
                <mesh filename="package://niryo_one_description/meshes/v2/collada/elbow_link.dae" />
            </geometry>
        </visual>
        <collision>
            <origin rpy="0 0 0" xyz="0 0 0" />
            <geometry>
                <mesh filename="package://niryo_one_description/meshes/v2/stl/elbow_link.stl" />
            </geometry>
        </collision>
        
        <inertial>
            <origin rpy="0 0 0" xyz="0 0 0" />
            <mass value="0.4" />
            <inertia ixx="1.0" ixy="0.0" ixz="0.0" iyy="1.0" iyz="0.0" izz="1.0" />
        </inertial>

    </link>
    <link name="forearm_link">
        <visual>
            <origin rpy="0 0 0" xyz="0 0 0" />
            <geometry>
                <mesh filename="package://niryo_one_description/meshes/v2/collada/forearm_link.dae" />
            </geometry>
        </visual>
        <collision>
            <origin rpy="0 0 0" xyz="0 0 0" />
            <geometry>
                <mesh filename="package://niryo_one_description/meshes/v2/stl/forearm_link.stl" />
            </geometry>
        </collision>
        
        <inertial>
            <origin rpy="0 0 0" xyz="0 0 0" />
            <mass value="0.3" />
            <inertia ixx="1.0" ixy="0.0" ixz="0.0" iyy="1.0" iyz="0.0" izz="1.0" />
        </inertial>

    </link>
    <link name="wrist_link">
        <visual>
            <origin rpy="0 0 0" xyz="0 0 0" />
            <geometry>
                <mesh filename="package://niryo_one_description/meshes/v2/collada/wrist_link.dae" />
            </geometry>
        </visual>
        <collision>
            <origin rpy="0 0 0" xyz="0 0 0" />
            <geometry>
                <mesh filename="package://niryo_one_description/meshes/v2/stl/wrist_link.stl" />
            </geometry>
        </collision>
        
        <inertial>
            <origin rpy="0 0 0" xyz="0 0 0" />
            <mass value="0.2" />
            <inertia ixx="1.0" ixy="0.0" ixz="0.0" iyy="1.0" iyz="0.0" izz="1.0" />
        </inertial>

    </link>
    <link name="hand_link">
        <visual>
            <origin rpy="0 0 0" xyz="0 0 0" />
            <geometry>
                <mesh filename="package://niryo_one_description/meshes/v2/collada/hand_link.dae" />
            </geometry>
        </visual>
        <collision>
            <origin rpy="0 0 0" xyz="0 0 0" />
            <geometry>
                <mesh filename="package://niryo_one_description/meshes/v2/stl/hand_link.stl" />
            </geometry>
        </collision>
        
        <inertial>
            <origin rpy="0 0 0" xyz="0 0 0" />
            <mass value="0.1" />
            <inertia ixx="1.0" ixy="0.0" ixz="0.0" iyy="1.0" iyz="0.0" izz="1.0" />
        </inertial>

    </link>
    <link name="tool_link" />
    <link name="spoon_holder_link">
        <visual>
            <origin rpy="0 0 0" xyz="0 0 0" />
            <geometry>
                <mesh filename="package://feedbot_description/meshes/feedbot_parts/collada/spoon_holder.dae" />
            </geometry>
        </visual>
        <collision>
            <origin rpy="0 0 0" xyz="0 0 0" />
            <geometry>
                <mesh filename="package://feedbot_description/meshes/feedbot_parts/stl/spoon_holder.stl" />
            </geometry>
        </collision>
        
        <inertial>
            <origin rpy="0 0 0" xyz="0 0 0" />
            <mass value="0.1" />
            <inertia ixx="1.0" ixy="0.0" ixz="0.0" iyy="1.0" iyz="0.0" izz="1.0" />
        </inertial>

    </link>
    <link name="spoon_link" />
    <!--Joints -->
    <joint name="ground_joint" type="fixed">
        <parent link="ground_link" />
        <child link="base_link" />
        <origin rpy="0 0 0" xyz="0 0 0" />
    </joint>
    <joint name="joint_1" type="revolute">
        <parent link="base_link" />
        <child link="shoulder_link" />
        <origin rpy="0 0 0" xyz="0 0 0.103" />
        <axis xyz="0 0 1" />
        <limit effort="1" lower="-3.05433" upper="3.05433" velocity="1.0" />
    </joint>
    <joint name="joint_2" type="revolute">
        <parent link="shoulder_link" />
        <child link="arm_link" />
        <origin rpy="1.5707963268 -1.5707963268 0" xyz="0 0 0.08" />
        <limit effort="1" lower="-1.91986" upper="0.640187" velocity="1.0" />
        <axis xyz="0 0 1" />
    </joint>
    <joint name="joint_3" type="revolute">
        <parent link="arm_link" />
        <child link="elbow_link" />
        <origin rpy="0 0 -1.5707963268" xyz="0.21 0.0 0" />
        <limit effort="1" lower="-1.397485" upper="1.5707963268" velocity="1.0" />
        <axis xyz="0 0 1" />
    </joint>
    <joint name="joint_4" type="revolute">
        <parent link="elbow_link" />
        <child link="forearm_link" />
        <origin rpy="0 1.5707963268 0" xyz="0.0415 0.03 0" />
        <limit effort="1" lower="-3.05433" upper="3.05433" velocity="1.0" />
        <axis xyz="0 0 1" />
    </joint>
    <joint name="joint_5" type="revolute">
        <parent link="forearm_link" />
        <child link="wrist_link" />
        <origin rpy="0 -1.5707963268 0" xyz="0 0 0.18" />
        <limit effort="1" lower="-1.74533" upper="1.91986" velocity="1.0" />
        <axis xyz="0 0 1" />
    </joint>
    <joint name="joint_6" type="revolute">
        <parent link="wrist_link" />
        <child link="hand_link" />
        <origin rpy="0 1.5707963268 0" xyz="0.0164 -0.0055 0" />
        <limit effort="1" lower="-2.57436" upper="2.57436" velocity="1.0" />
        <axis xyz="0 0 1" />
    </joint>
    <joint name="hand_tool_joint" type="fixed">
        <parent link="hand_link" />
        <child link="tool_link" />
        <origin rpy="-1.5707963268 -1.5707963268 0" xyz="0 0 0.0073" />
    </joint>
    <joint name="spoon_holder_joint" type="fixed">
        <parent link="tool_link" />
        <child link="spoon_holder_link" />
        <origin rpy="0 0 0" xyz="0 0 0" />
    </joint>
    <joint name="spoon_joint" type="fixed">
        <parent link="spoon_holder_link" />
        <child link="spoon_link" />
        <origin rpy="0 0 0" xyz="0.06 0.171 -0.016" />
    </joint>
    <gazebo>
        <plugin filename="libgazebo_ros_control.so" name="gazebo_ros_control" />
    </gazebo>
    <transmission name="trans_joint_1">
        <type>transmission_interface/SimpleTransmission</type>
        <joint name="joint_1">
            <hardwareInterface>hardware_interface/EffortJointInterface</hardwareInterface>
        </joint>
        <actuator name="joint_1_motor">
            <hardwareInterface>hardware_interface/EffortJointInterface</hardwareInterface>
            <mechanicalReduction>1</mechanicalReduction>
        </actuator>
    </transmission>
    <transmission name="trans_joint_2">
        <type>transmission_interface/SimpleTransmission</type>
        <joint name="joint_2">
            <hardwareInterface>hardware_interface/EffortJointInterface</hardwareInterface>
        </joint>
        <actuator name="joint_2_motor">
            <hardwareInterface>hardware_interface/EffortJointInterface</hardwareInterface>
            <mechanicalReduction>1</mechanicalReduction>
        </actuator>
    </transmission>
    <transmission name="trans_joint_3">
        <type>transmission_interface/SimpleTransmission</type>
        <joint name="joint_3">
            <hardwareInterface>hardware_interface/EffortJointInterface</hardwareInterface>
        </joint>
        <actuator name="joint_3_motor">
            <hardwareInterface>hardware_interface/EffortJointInterface</hardwareInterface>
            <mechanicalReduction>1</mechanicalReduction>
        </actuator>
    </transmission>
    <transmission name="trans_joint_4">
        <type>transmission_interface/SimpleTransmission</type>
        <joint name="joint_4">
            <hardwareInterface>hardware_interface/EffortJointInterface</hardwareInterface>
        </joint>
        <actuator name="joint_4_motor">
            <hardwareInterface>hardware_interface/EffortJointInterface</hardwareInterface>
            <mechanicalReduction>1</mechanicalReduction>
        </actuator>
    </transmission>
    <transmission name="trans_joint_5">
        <type>transmission_interface/SimpleTransmission</type>
        <joint name="joint_5">
            <hardwareInterface>hardware_interface/EffortJointInterface</hardwareInterface>
        </joint>
        <actuator name="joint_5_motor">
            <hardwareInterface>hardware_interface/EffortJointInterface</hardwareInterface>
            <mechanicalReduction>1</mechanicalReduction>
        </actuator>
    </transmission>
    <transmission name="trans_joint_6">
        <type>transmission_interface/SimpleTransmission</type>
        <joint name="joint_6">
            <hardwareInterface>hardware_interface/EffortJointInterface</hardwareInterface>
        </joint>
        <actuator name="joint_6_motor">
            <hardwareInterface>hardware_interface/EffortJointInterface</hardwareInterface>
            <mechanicalReduction>1</mechanicalReduction>
        </actuator>
    </transmission>
    <gazebo>
        <plugin name="gazebo_ros_control" filename="libgazebo_ros_control.so">
            <robotNamespace>/</robotNamespace>
        </plugin>
    </gazebo>
</robot>